Workbook

Sheet Existencias
A2: Código | B2: Proveedor (código) | C2: Proveedor | D2: Detalle | E2: Nombre del artículo2 | F2: Precio de venta | G2: Precio de venta2 | H2: Existencias mínimas | I2: Existencias iniciales | J2: Entradas | K2: Salidas | L2: Existencias actuales | M2: Columna1 | N2: Detalle del artículo2
A3: 0001ME | B3: 1 | C3: =IF([1]!Artículos4[[#This Row],[Proveedor (código)]]="","",VLOOKUP([2]!Artículos4[[#This Row],[Proveedor (código)]],[2]Proveedores!A:B,2,FALSE)) -> #REF! | D3: Arverja partida 500 gr | E3: Menestras | F3: 3.9 | I3: 29 | J3: =SUMIFS(Entradas!G:G,Entradas!E:E,Artículos[[#This Row],[Código]]) -> 3 | K3: =SUMIFS(Salidas!G:G,Salidas!E:E,#REF!) -> 0 | L3: =Artículos[[#This Row],[Existencias iniciales]]+Artículos[[#This Row],[Entradas]]-Artículos[[#This Row],[Salidas]] -> 32 | M3: Maizena
A4: 0002ME | C4: =IF([2]!Artículos4[[#This Row],[Proveedor (código)]]="","",VLOOKUP([2]!Artículos4[[#This Row],[Proveedor (código)]],[2]Proveedores!A:B,2,FALSE)) -> #REF! | D4: Arverja partida 1 kg | E4: Menestras | F4: 6.1 | J4: =SUMIFS(Entradas!G:G,Entradas!E:E,Artículos[[#This Row],[Código]]) -> 0 | K4: =SUMIFS(Salidas!G:G,Salidas!E:E,Artículos[[#This Row],[Código]]) -> 3 | L4: =Artículos[[#This Row],[Existencias iniciales]]+Artículos[[#This Row],[Entradas]]-Artículos[[#This Row],[Salidas]] -> -3 | M4: Maizena
A5: 0003ME | B5: 1 | C5: =IF([2]!Artículos4[[#This Row],[Proveedor (código)]]="","",VLOOKUP([2]!Artículos4[[#This Row],[Proveedor (código)]],[2]Proveedores!A:B,2,FALSE)) -> #REF! | D5: Arverja partida 10 kg | E5: Menestras | F5: 71.1 | I5: 2 | J5: =SUMIFS(Entradas!G:G,Entradas!E:E,Artículos[[#This Row],[Código]]) -> 0 | K5: =SUMIFS(Salidas!G:G,Salidas!E:E,Artículos[[#This Row],[Código]]) -> 0 | L5: =Artículos[[#This Row],[Existencias iniciales]]+Artículos[[#This Row],[Entradas]]-Artículos[[#This Row],[Salidas]] -> 2 | M5: Maizena
A6: 0004ME | B6: 1 | C6: =IF([2]!Artículos4[[#This Row],[Proveedor (código)]]="","",VLOOKUP([2]!Artículos4[[#This Row],[Proveedor (código)]],[2]Proveedores!A:B,2,FALSE)) -> #REF! | D6: Arverja partida 5 kl gr | E6: Menestras | F6: 36.9 | I6: 7 | J6: =SUMIFS(Entradas!G:G,Entradas!E:E,Artículos[[#This Row],[Código]]) -> 0 | K6: =SUMIFS(Salidas!G:G,Salidas!E:E,Artículos[[#This Row],[Código]]) -> 0 | L6: =Artículos[[#This Row],[Existencias iniciales]]+Artículos[[#This Row],[Entradas]]-Artículos[[#This Row],[Salidas]] -> 7 | M6: Maizena
A7: 0005ME | C7: =IF([2]!Artículos4[[#This Row],[Proveedor (código)]]="","",VLOOKUP([2]!Artículos4[[#This Row],[Proveedor (código)]],[2]Proveedores!A:B,2,FALSE)) -> #REF! | D7: Arverja partida 20 kg | E7: Menestras | I7: 4 | J7: =SUMIFS(Entradas!G:G,Entradas!E:E,Artículos[[#This Row],[Código]]) -> 0 | K7: =SUMIFS(Salidas!G:G,Salidas!E:E,Artículos[[#This Row],[Código]]) -> 0 | L7: =Artículos[[#This Row],[Existencias iniciales]]+Artículos[[#This Row],[Entradas]]-Artículos[[#This Row],[Salidas]] -> 4 | M7: Maizena
A8: 0006ME | B8: 1 | C8: =IF([2]!Artículos4[[#This Row],[Proveedor (código)]]="","",VLOOKUP([2]!Artículos4[[#This Row],[Proveedor (código)]],[2]Proveedores!A:B,2,FALSE)) -> #REF! | D8: Frejol Bayo 500 gr | E8: Menestras | F8: 4.5 | J8: =SUMIFS(Entradas!G:G,Entradas!E:E,Artículos[[#This Row],[Código]]) -> 0 | K8: =SUMIFS(Salidas!G:G,Salidas!E:E,Artículos[[#This Row],[Código]]) -> 0 | L8: =Artículos[[#This Row],[Existencias iniciales]]+Artículos[[#This Row],[Entradas]]-Artículos[[#This Row],[Salidas]] -> 0 | M8: Mazamorra
A9: 0007ME | B9: 1 | C9: =IF([2]!Artículos4[[#This Row],[Proveedor (código)]]="","",VLOOKUP([2]!Artículos4[[#This Row],[Proveedor (código)]],[2]Proveedores!A:B,2,FALSE)) -> #REF! | D9: Frejol Bayo 1 kl | E9: Menestras | F9: 6.5 | J9: =SUMIFS(Entradas!G:G,Entradas!E:E,Artículos[[#This Row],[Código]]) -> 0 | K9: =SUMIFS(Salidas!G:G,Salidas!E:E,Artículos[[#This Row],[Código]]) -> 0 | L9: =Artículos[[#This Row],[Existencias iniciales]]+Artículos[[#This Row],[Entradas]]-Artículos[[#This Row],[Salidas]] -> 0 | M9: Mermelada
A10: 0008ME | C10: =IF([2]!Artículos4[[#This Row],[Proveedor (código)]]="","",VLOOKUP([2]!Artículos4[[#This Row],[Proveedor (código)]],[2]Proveedores!A:B,2,FALSE)) -> #REF! | D10: Frejol Caballero 5 kl | E10: Menestras | J10: =SUMIFS(Entradas!G:G,Entradas!E:E,Artículos[[#This Row],[Código]]) -> 0 | K10: =SUMIFS(Salidas!G:G,Salidas!E:E,Artículos[[#This Row],[Código]]) -> 0 | L10: =Artículos[[#This Row],[Existencias iniciales]]+Artículos[[#This Row],[Entradas]]-Artículos[[#This Row],[Salidas]] -> 0 | M10: Cocoa
A11: 0009ME | B11: 1 | C11: =IF([2]!Artículos4[[#This Row],[Proveedor (código)]]="","",VLOOKUP([2]!Artículos4[[#This Row],[Proveedor (código)]],[2]Proveedores!A:B,2,FALSE)) -> #REF! | D11: Frejol Caballero 500 gr | E11: Menestras | J11: =SUMIFS(Entradas!G:G,Entradas!E:E,Artículos[[#This Row],[Código]]) -> 0 | K11: =SUMIFS(Salidas!G:G,Salidas!E:E,Artículos[[#This Row],[Código]]) -> 0 | L11: =Artículos[[#This Row],[Existencias iniciales]]+Artículos[[#This Row],[Entradas]]-Artículos[[#This Row],[Salidas]] -> 0 | M11: Cocoa
A12: 0010ME | B12: 1 | C12: =IF([2]!Artículos4[[#This Row],[Proveedor (código)]]="","",VLOOKUP([2]!Artículos4[[#This Row],[Proveedor (código)]],[2]Proveedores!A:B,2,FALSE)) -> #REF! | D12: Frejol Caballlero 1 kg | E12: Menestras | J12: =SUMIFS(Entradas!G:G,Entradas!E:E,Artículos[[#This Row],[Código]]) -> 0 | K12: =SUMIFS(Salidas!G:G,Salidas!E:E,Artículos[[#This Row],[Código]]) -> 0 | L12: =Artículos[[#This Row],[Existencias iniciales]]+Artículos[[#This Row],[Entradas]]-Artículos[[#This Row],[Salidas]] -> 0 | M12: Menestras
A13: 0011ME | C13: =IF([2]!Artículos4[[#This Row],[Proveedor (código)]]="","",VLOOKUP([2]!Artículos4[[#This Row],[Proveedor (código)]],[2]Proveedores!A:B,2,FALSE)) -> #REF! | D13: Frejol Caballero 5 kg | E13: Menestras | J13: =SUMIFS(Entradas!G:G,Entradas!E:E,Artículos[[#This Row],[Código]]) -> 0 | K13: =SUMIFS(Salidas!G:G,Salidas!E:E,Artículos[[#This Row],[Código]]) -> 0 | L13: =Artículos[[#This Row],[Existencias iniciales]]+Artículos[[#This Row],[Entradas]]-Artículos[[#This Row],[Salidas]] -> 0 | M13: Especies
A14: 0012ME | B14: 1 | C14: =IF([2]!Artículos4[[#This Row],[Proveedor (código)]]="","",VLOOKUP([2]!Artículos4[[#This Row],[Proveedor (código)]],[2]Proveedores!A:B,2,FALSE)) -> #REF! | D14: Frejol Caballlero 10 kl | E14: Menestras | J14: =SUMIFS(Entradas!G:G,Entradas!E:E,Artículos[[#This Row],[Código]]) -> 0 | K14: =SUMIFS(Salidas!G:G,Salidas!E:E,Artículos[[#This Row],[Código]]) -> 0 | L14: =Artículos[[#This Row],[Existencias iniciales]]+Artículos[[#This Row],[Entradas]]-Artículos[[#This Row],[Salidas]] -> 0 | M14: Especies
A15: 0013ME | B15: 1 | C15: =IF([2]!Artículos4[[#This Row],[Proveedor (código)]]="","",VLOOKUP([2]!Artículos4[[#This Row],[Proveedor (código)]],[2]Proveedores!A:B,2,FALSE)) -> #REF! | D15: Frejol Canario 500 gr | E15: Menestras | F15: 7.9 | I15: 4 | J15: =SUMIFS(Entradas!G:G,Entradas!E:E,Artículos[[#This Row],[Código]]) -> 2 | K15: =SUMIFS(Salidas!G:G,Salidas!E:E,Artículos[[#This Row],[Código]]) -> 0 | L15: =Artículos[[#This Row],[Existencias iniciales]]+Artículos[[#This Row],[Entradas]]-Artículos[[#This Row],[Salidas]] -> 6 | M15: Menestras
A16: 0014ME | C16: =IF([2]!Artículos4[[#This Row],[Proveedor (código)]]="","",VLOOKUP([2]!Artículos4[[#This Row],[Proveedor (código)]],[2]Proveedores!A:B,2,FALSE)) -> #REF! | D16: Frejol Canario 1 kg | E16: Menestras | I16: 17 | J16: =SUMIFS(Entradas!G:G,Entradas!E:E,Artículos[[#This Row],[Código]]) -> 0 | K16: =SUMIFS(Salidas!G:G,Salidas!E:E,Artículos[[#This Row],[Código]]) -> 0 | L16: =Artículos[[#This Row],[Existencias iniciales]]+Artículos[[#This Row],[Entradas]]-Artículos[[#This Row],[Salidas]] -> 17 | M16: Menestras
A17: 0015ME | B17: 1 | C17: =IF([2]!Artículos4[[#This Row],[Proveedor (código)]]="","",VLOOKUP([2]!Artículos4[[#This Row],[Proveedor (código)]],[2]Proveedores!A:B,2,FALSE)) -> #REF! | D17: Frejol Canario 5kg | E17: Menestras | I17: 19 | J17: =SUMIFS(Entradas!G:G,Entradas!E:E,Artículos[[#This Row],[Código]]) -> 0 | K17: =SUMIFS(Salidas!G:G,Salidas!E:E,Artículos[[#This Row],[Código]]) -> 0 | L17: =Artículos[[#This Row],[Existencias iniciales]]+Artículos[[#This Row],[Entradas]]-Artículos[[#This Row],[Salidas]] -> 19 | M17: Menestras
A18: 0016ME | B18: 1 | C18: =IF([2]!Artículos4[[#This Row],[Proveedor (código)]]="","",VLOOKUP([2]!Artículos4[[#This Row],[Proveedor (código)]],[2]Proveedores!A:B,2,FALSE)) -> #REF! | D18: Frejol Canario 10 | E18: Menestras | I18: 5 | J18: =SUMIFS(Entradas!G:G,Entradas!E:E,Artículos[[#This Row],[Código]]) -> 0 | K18: =SUMIFS(Salidas!G:G,Salidas!E:E,Artículos[[#This Row],[Código]]) -> 0 | L18: =Artículos[[#This Row],[Existencias iniciales]]+Artículos[[#This Row],[Entradas]]-Artículos[[#This Row],[Salidas]] -> 5 | M18: Menestras
A19: 0017ME | B19: 1 | C19: =IF([2]!Artículos4[[#This Row],[Proveedor (código)]]="","",VLOOKUP([2]!Artículos4[[#This Row],[Proveedor (código)]],[2]Proveedores!A:B,2,FALSE)) -> #REF! | D19: Frejol Castilla 500 gr | E19: Menestras | J19: =SUMIFS(Entradas!G:G,Entradas!E:E,Artículos[[#This Row],[Código]]) -> 0 | K19: =SUMIFS(Salidas!G:G,Salidas!E:E,Artículos[[#This Row],[Código]]) -> 0 | L19: =Artículos[[#This Row],[Existencias iniciales]]+Artículos[[#This Row],[Entradas]]-Artículos[[#This Row],[Salidas]] -> 0 | M19: Paneton
A20: 0018ME | B20: 1 | C20: =IF([2]!Artículos4[[#This Row],[Proveedor (código)]]="","",VLOOKUP([2]!Artículos4[[#This Row],[Proveedor (código)]],[2]Proveedores!A:B,2,FALSE)) -> #REF! | D20: Frejol Castilla 1 kg | E20: Menestras | J20: =SUMIFS(Entradas!G:G,Entradas!E:E,Artículos[[#This Row],[Código]]) -> 0 | K20: =SUMIFS(Salidas!G:G,Salidas!E:E,Artículos[[#This Row],[Código]]) -> 3 | L20: =Artículos[[#This Row],[Existencias iniciales]]+Artículos[[#This Row],[Entradas]]-Artículos[[#This Row],[Salidas]] -> -3 | M20: Menestras
A21: 0019ME | B21: 1 | C21: =IF([2]!Artículos4[[#This Row],[Proveedor (código)]]="","",VLOOKUP([2]!Artículos4[[#This Row],[Proveedor (código)]],[2]Proveedores!A:B,2,FALSE)) -> #REF! | D21: Frejol Castilla 5 kl | E21: Menestras | I21: 5 | J21: =SUMIFS(Entradas!G:G,Entradas!E:E,Artículos[[#This Row],[Código]]) -> 0 | K21: =SUMIFS(Salidas!G:G,Salidas!E:E,Artículos[[#This Row],[Código]]) -> 0 | L21: =Artículos[[#This Row],[Existencias iniciales]]+Artículos[[#This Row],[Entradas]]-Artículos[[#This Row],[Salidas]] -> 5 | M21: Menestras
A22: 0020ME | B22: 1 | C22: =IF([2]!Artículos4[[#This Row],[Proveedor (código)]]="","",VLOOKUP([2]!Artículos4[[#This Row],[Proveedor (código)]],[2]Proveedores!A:B,2,FALSE)) -> #REF! | D22: Frejol Castilla 10 kg | E22: Menestras | J22: =SUMIFS(Entradas!G:G,Entradas!E:E,Artículos[[#This Row],[Código]]) -> 0 | K22: =SUMIFS(Salidas!G:G,Salidas!E:E,Artículos[[#This Row],[Código]]) -> 0 | L22: =Artículos[[#This Row],[Existencias iniciales]]+Artículos[[#This Row],[Entradas]]-Artículos[[#This Row],[Salidas]] -> 0 | M22: Menestras
A23: 0021ME | C23: =IF([2]!Artículos4[[#This Row],[Proveedor (código)]]="","",VLOOKUP([2]!Artículos4[[#This Row],[Proveedor (código)]],[2]Proveedores!A:B,2,FALSE)) -> #REF! | D23: Frejol Negro 500 gr | E23: Menestras | F23: 5.91 | J23: =SUMIFS(Entradas!G:G,Entradas!E:E,Artículos[[#This Row],[Código]]) -> 2 | K23: =SUMIFS(Salidas!G:G,Salidas!E:E,Artículos[[#This Row],[Código]]) -> 0 | L23: =Artículos[[#This Row],[Existencias iniciales]]+Artículos[[#This Row],[Entradas]]-Artículos[[#This Row],[Salidas]] -> 2 | M23: Menestras
A24: 0022ME | C24: =IF([2]!Artículos4[[#This Row],[Proveedor (código)]]="","",VLOOKUP([2]!Artículos4[[#This Row],[Proveedor (código)]],[2]Proveedores!A:B,2,FALSE)) -> #REF! | D24: Frejol Negro 1 kl | E24: Menestras | J24: =SUMIFS(Entradas!G:G,Entradas!E:E,Artículos[[#This Row],[Código]]) -> 0 | K24: =SUMIFS(Salidas!G:G,Salidas!E:E,Artículos[[#This Row],[Código]]) -> 0 | L24: =Artículos[[#This Row],[Existencias iniciales]]+Artículos[[#This Row],[Entradas]]-Artículos[[#This Row],[Salidas]] -> 0 | M24: Menestras
A25: 0023ME | C25: =IF([2]!Artículos4[[#This Row],[Proveedor (código)]]="","",VLOOKUP([2]!Artículos4[[#This Row],[Proveedor (código)]],[2]Proveedores!A:B,2,FALSE)) -> #REF! | D25: Frejol Negro 5 kl | E25: Menestras | I25: 1 | J25: =SUMIFS(Entradas!G:G,Entradas!E:E,Artículos[[#This Row],[Código]]) -> 0 | K25: =SUMIFS(Salidas!G:G,Salidas!E:E,Artículos[[#This Row],[Código]]) -> 0 | L25: =Artículos[[#This Row],[Existencias iniciales]]+Artículos[[#This Row],[Entradas]]-Artículos[[#This Row],[Salidas]] -> 1 | M25: Menestras
A26: 0024ME | D26: Frejol Panamito 500 gr | E26: Menestras | F26: 6.89 | I26: 6 | J26: =SUMIFS(Entradas!G:G,Entradas!E:E,Artículos[[#This Row],[Código]]) -> 1 | K26: =SUMIFS(Salidas!G:G,Salidas!E:E,Artículos[[#This Row],[Código]]) -> 0 | L26: =Artículos[[#This Row],[Existencias iniciales]]+Artículos[[#This Row],[Entradas]]-Artículos[[#This Row],[Salidas]] -> 7 | M26: Menestras
A27: 0025ME | C27: =IF([2]!Artículos4[[#This Row],[Proveedor (código)]]="","",VLOOKUP([2]!Artículos4[[#This Row],[Proveedor (código)]],[2]Proveedores!A:B,2,FALSE)) -> #REF! | D27: Frejol Panamito 1 kg | E27: Menestras | I27: 4 | J27: =SUMIFS(Entradas!G:G,Entradas!E:E,Artículos[[#This Row],[Código]]) -> 0 | K27: =SUMIFS(Salidas!G:G,Salidas!E:E,Artículos[[#This Row],[Código]]) -> 0 | L27: =Artículos[[#This Row],[Existencias iniciales]]+Artículos[[#This Row],[Entradas]]-Artículos[[#This Row],[Salidas]] -> 4 | M27: Salsa de Tomate
A28: 0026ME | C28: =IF([2]!Artículos4[[#This Row],[Proveedor (código)]]="","",VLOOKUP([2]!Artículos4[[#This Row],[Proveedor (código)]],[2]Proveedores!A:B,2,FALSE)) -> #REF! | D28: Frejol Panamito 5 kg | E28: Menestras | I28: 1 | J28: =SUMIFS(Entradas!G:G,Entradas!E:E,Artículos[[#This Row],[Código]]) -> 0 | K28: =SUMIFS(Salidas!G:G,Salidas!E:E,Artículos[[#This Row],[Código]]) -> 0 | L28: =Artículos[[#This Row],[Existencias iniciales]]+Artículos[[#This Row],[Entradas]]-Artículos[[#This Row],[Salidas]] -> 1
A29: 0027ME | C29: =IF([2]!Artículos4[[#This Row],[Proveedor (código)]]="","",VLOOKUP([2]!Artículos4[[#This Row],[Proveedor (código)]],[2]Proveedores!A:B,2,FALSE)) -> #REF! | D29: Frejol Panamito 10 kg | E29: Menestras | I29: 2 | J29: =SUMIFS(Entradas!G:G,Entradas!E:E,Artículos[[#This Row],[Código]]) -> 0 | K29: =SUMIFS(Salidas!G:G,Salidas!E:E,Artículos[[#This Row],[Código]]) -> 0 | L29: =Artículos[[#This Row],[Existencias iniciales]]+Artículos[[#This Row],[Entradas]]-Artículos[[#This Row],[Salidas]] -> 2
A30: 0028ME | C30: =IF([2]!Artículos4[[#This Row],[Proveedor (código)]]="","",VLOOKUP([2]!Artículos4[[#This Row],[Proveedor (código)]],[2]Proveedores!A:B,2,FALSE)) -> #REF! | D30: Frejol Rojo 500 gr | E30: Menestras | F30: 6.7 | I30: 1 | J30: =SUMIFS(Entradas!G:G,Entradas!E:E,Artículos[[#This Row],[Código]]) -> 0 | K30: =SUMIFS(Salidas!G:G,Salidas!E:E,Artículos[[#This Row],[Código]]) -> 0 | L30: =Artículos[[#This Row],[Existencias iniciales]]+Artículos[[#This Row],[Entradas]]-Artículos[[#This Row],[Salidas]] -> 1
A31: 0029ME | C31: =IF([2]!Artículos4[[#This Row],[Proveedor (código)]]="","",VLOOKUP([2]!Artículos4[[#This Row],[Proveedor (código)]],[2]Proveedores!A:B,2,FALSE)) -> #REF! | D31: Frejol Rojo 1 kl | E31: Menestras | J31: =SUMIFS(Entradas!G:G,Entradas!E:E,Artículos[[#This Row],[Código]]) -> 0 | K31: =SUMIFS(Salidas!G:G,Salidas!E:E,Artículos[[#This Row],[Código]]) -> 0 | L31: =Artículos[[#This Row],[Existencias iniciales]]+Artículos[[#This Row],[Entradas]]-Artículos[[#This Row],[Salidas]] -> 0
A32: 0030ME | C32: =IF([2]!Artículos4[[#This Row],[Proveedor (código)]]="","",VLOOKUP([2]!Artículos4[[#This Row],[Proveedor (código)]],[2]Proveedores!A:B,2,FALSE)) -> #REF! | D32: Garbanzo 500gr | E32: Menestras | I32: 11 | J32: =SUMIFS(Entradas!G:G,Entradas!E:E,Artículos[[#This Row],[Código]]) -> 3 | K32: =SUMIFS(Salidas!G:G,Salidas!E:E,Artículos[[#This Row],[Código]]) -> 0 | L32: =Artículos[[#This Row],[Existencias iniciales]]+Artículos[[#This Row],[Entradas]]-Artículos[[#This Row],[Salidas]] -> 14
A33: 0031ME | C33: =IF([2]!Artículos4[[#This Row],[Proveedor (código)]]="","",VLOOKUP([2]!Artículos4[[#This Row],[Proveedor (código)]],[2]Proveedores!A:B,2,FALSE)) -> #REF! | D33: Garbanzo 1 kl | E33: Menestras | I33: 4 | J33: =SUMIFS(Entradas!G:G,Entradas!E:E,Artículos[[#This Row],[Código]]) -> 0 | K33: =SUMIFS(Salidas!G:G,Salidas!E:E,Artículos[[#This Row],[Código]]) -> 0 | L33: =Artículos[[#This Row],[Existencias iniciales]]+Artículos[[#This Row],[Entradas]]-Artículos[[#This Row],[Salidas]] -> 4
A34: 0032ME | C34: =IF([2]!Artículos4[[#This Row],[Proveedor (código)]]="","",VLOOKUP([2]!Artículos4[[#This Row],[Proveedor (código)]],[2]Proveedores!A:B,2,FALSE)) -> #REF! | D34: Garbanzo 5 kg | E34: Menestras | J34: =SUMIFS(Entradas!G:G,Entradas!E:E,Artículos[[#This Row],[Código]]) -> 0 | K34: =SUMIFS(Salidas!G:G,Salidas!E:E,Artículos[[#This Row],[Código]]) -> 0 | L34: =Artículos[[#This Row],[Existencias iniciales]]+Artículos[[#This Row],[Entradas]]-Artículos[[#This Row],[Salidas]] -> 0
A35: 0033ME | C35: =IF([2]!Artículos4[[#This Row],[Proveedor (código)]]="","",VLOOKUP([2]!Artículos4[[#This Row],[Proveedor (código)]],[2]Proveedores!A:B,2,FALSE)) -> #REF! | D35: Garbanzo 10 kg | E35: Menestras | J35: =SUMIFS(Entradas!G:G,Entradas!E:E,Artículos[[#This Row],[Código]]) -> 0 | K35: =SUMIFS(Salidas!G:G,Salidas!E:E,Artículos[[#This Row],[Código]]) -> 0 | L35: =Artículos[[#This Row],[Existencias iniciales]]+Artículos[[#This Row],[Entradas]]-Artículos[[#This Row],[Salidas]] -> 0
A36: 0034ME | C36: =IF([2]!Artículos4[[#This Row],[Proveedor (código)]]="","",VLOOKUP([2]!Artículos4[[#This Row],[Proveedor (código)]],[2]Proveedores!A:B,2,FALSE)) -> #REF! | D36: Lenteja 500 gr | E36: Menestras | F36: 2.92 | I36: 43 | J36: =SUMIFS(Entradas!G:G,Entradas!E:E,Artículos[[#This Row],[Código]]) -> 3 | K36: =SUMIFS(Salidas!G:G,Salidas!E:E,Artículos[[#This Row],[Código]]) -> 9 | L36: =Artículos[[#This Row],[Existencias iniciales]]+Artículos[[#This Row],[Entradas]]-Artículos[[#This Row],[Salidas]] -> 37
A37: 0035ME | C37: =IF([2]!Artículos4[[#This Row],[Proveedor (código)]]="","",VLOOKUP([2]!Artículos4[[#This Row],[Proveedor (código)]],[2]Proveedores!A:B,2,FALSE)) -> #REF! | D37: Lenteja 1 kg | E37: Menestras | I37: 22 | J37: =SUMIFS(Entradas!G:G,Entradas!E:E,Artículos[[#This Row],[Código]]) -> 0 | K37: =SUMIFS(Salidas!G:G,Salidas!E:E,Artículos[[#This Row],[Código]]) -> 5 | L37: =Artículos[[#This Row],[Existencias iniciales]]+Artículos[[#This Row],[Entradas]]-Artículos[[#This Row],[Salidas]] -> 17
A38: 0036ME | C38: =IF([2]!Artículos4[[#This Row],[Proveedor (código)]]="","",VLOOKUP([2]!Artículos4[[#This Row],[Proveedor (código)]],[2]Proveedores!A:B,2,FALSE)) -> #REF! | D38: Lenteja 5kg | E38: Menestras | I38: 8 | J38: =SUMIFS(Entradas!G:G,Entradas!E:E,Artículos[[#This Row],[Código]]) -> 0 | K38: =SUMIFS(Salidas!G:G,Salidas!E:E,Artículos[[#This Row],[Código]]) -> 0 | L38: =Artículos[[#This Row],[Existencias iniciales]]+Artículos[[#This Row],[Entradas]]-Artículos[[#This Row],[Salidas]] -> 8
A39: 0037ME | C39: =IF([2]!Artículos4[[#This Row],[Proveedor (código)]]="","",VLOOKUP([2]!Artículos4[[#This Row],[Proveedor (código)]],[2]Proveedores!A:B,2,FALSE)) -> #REF! | D39: Lenteja 10 kg | E39: Menestras | I39: 12 | J39: =SUMIFS(Entradas!G:G,Entradas!E:E,Artículos[[#This Row],[Código]]) -> 0 | K39: =SUMIFS(Salidas!G:G,Salidas!E:E,Artículos[[#This Row],[Código]]) -> 0 | L39: =Artículos[[#This Row],[Existencias iniciales]]+Artículos[[#This Row],[Entradas]]-Artículos[[#This Row],[Salidas]] -> 12
A40: 0038ME | C40: =IF([2]!Artículos4[[#This Row],[Proveedor (código)]]="","",VLOOKUP([2]!Artículos4[[#This Row],[Proveedor (código)]],[2]Proveedores!A:B,2,FALSE)) -> #REF! | D40: Lenteja 50 kg | E40: Menestras | J40: =SUMIFS(Entradas!G:G,Entradas!E:E,Artículos[[#This Row],[Código]]) -> 0 | K40: =SUMIFS(Salidas!G:G,Salidas!E:E,Artículos[[#This Row],[Código]]) -> 0 | L40: =Artículos[[#This Row],[Existencias iniciales]]+Artículos[[#This Row],[Entradas]]-Artículos[[#This Row],[Salidas]] -> 0
A41: 0039ME | C41: =IF([2]!Artículos4[[#This Row],[Proveedor (código)]]="","",VLOOKUP([2]!Artículos4[[#This Row],[Proveedor (código)]],[2]Proveedores!A:B,2,FALSE)) -> #REF! | D41: Lenteja BB 500 gr | E41: Menestras | F41: 5.05 | J41: =SUMIFS(Entradas!G:G,Entradas!E:E,Artículos[[#This Row],[Código]]) -> 8 | K41: =SUMIFS(Salidas!G:G,Salidas!E:E,Artículos[[#This Row],[Código]]) -> 0 | L41: =Artículos[[#This Row],[Existencias iniciales]]+Artículos[[#This Row],[Entradas]]-Artículos[[#This Row],[Salidas]] -> 8
...

Sheet Hoja2
B2: Código | C2: Detalle | D2: Nombre del artículo2
B3: 0001ME | C3: Arverja partida 500 gr | D3: Menestras
B4: 0002ME | C4: Arverja partida 1 kg | D4: Menestras
B5: 0003ME | C5: Arverja partida 10 kg | D5: Menestras
B6: 0004ME | C6: Arverja partida 5 kl gr | D6: Menestras
B7: 0005ME | C7: Arverja partida 10 kg | D7: Menestras
B8: 0006ME | C8: Frejol Bayo 500 gr | D8: Menestras
B9: 0007ME | C9: Frejol Bayo 1 kl | D9: Menestras
B10: 0008ME | C10: Frejol Caballero 5 kl | D10: Menestras
B11: 0009ME | C11: Frejol Caballero 500 gr | D11: Menestras
B12: 0010ME | C12: Frejol Caballlero 1 kg | D12: Menestras
B13: 0011ME | C13: Frejol Caballero 5 kg | D13: Menestras
... B90: 0088ME | C90: Pop corn 5 kg | D90: Menestras
B91: 0089ME | D91: Menestras
B92: 0090AC | C92: Aceite Vegetal 900 ml | D92: Aceite
B93: 0091AC | C93: Aceite Vegetal 3 lt | D93: Aceite
B94: 0092AC | C94: Aceite Vegetal 5 lt | D94: Aceite
B95: 0093AC | C95: Aceite Vegetal 20 lt | D95: Aceite
B96: 0094AC | C96: Aceite Spray 200 ml | D96: Aceite
B97: 0095AC | C97: Aceite Soya 900 ml | D97: Aceite
B98: 0096AC | C98: Aceite Soya 5 lt | D98: Aceite
B99: 0097AC | C99: Aceite Soya 20 lt | D99: Aceite
B100: 0098AC | C100: Aceite de Oliva Virgen200 ml | D100: Aceite
B101: 0099AC | C101: Aceite de Oliva Virgen 900 ml | D101: Aceite
B102: 0100AC | C102: Aceite de Oliva Virgen 5 lt | D102: Aceite
B103: 0101AC | C103: Aceite de OlivaExtra Virgen200 ml | D103: Aceite
... B113: 0112AC | C113: Aceite de oliva 4 lt | D113: Aceite
B114: 0113AC | D114: Aceite
B115: 0114AC | D115: Aceite
B116: 0115CO | C116: Filete de atun agua lata | D116: Conserva
B117: 0116CO | C117: Filete de atun aceite lata | D117: Conserva
B118: 0117CO | C118: Trozo de atun agua lata | D118: Conserva
B119: 0118CO | C119: Trozo de atun aceite lata | D119: Conserva
B120: 0119CO | C120: Lomo de atun aceite lata | D120: Conserva
B121: 0120CO | C121: Lomo de atun agua lata | D121: Conserva
B122: 0121CO | C122: Solido de caballa lata | D122: Conserva
B123: 0122CO | C123: Filete de caballa lata | D123: Conserva
B124: 0123CO | C124: Filete de Bonito lata | D124: Conserva
B125: 0124CO | C125: Grated de Atun lata | D125: Conserva
B126: 0125CO | C126: Sardina lata | D126: Conserva
...

Sheet Proveedores
A2: Código | B2: Nombre fiscal | C2: Nombre | D2: Apellidos | E2: NIF/CIF | F2: Teléfono | G2: E-mail | H2: Dirección | I2: Población | J2: Provincia | K2: Código Postal
A3: 1 | B3: ALBERGUE | C3: ALDIMI | D3: Ejemplo | E3: 11111111Z | F3: 111111111 | G3: proveedor@ejemplo.com | H3: Calle 9 | I3: Ejemplo | J3: Ejemplo Proveedor | K3: 11111
A4: 2 | B4: PLAZA VEA B.A
A5: 3 | B5: FLORA Y FAUNA
A6: 4 | B6: Metro B.A
A7: 5 | B7: Almacen Banco de Alimentos
A8: 6 | B8: Gloria
A9: 7 | B9: frozen
A10: 8 | B10: MOR
A11: 9 | B11: Jorge Bustamante
A12: 10 | B12: Eggs
A13: 11 | B13: PLAZA VEA B.A
A14: 12 | B14: Pilar Coronado | F14: 992773897
A15: 13 | B15: Inspira B.A

Sheet Entradas
A2: Código | B2: Fecha | C2: Proveedor (código) | D2: Proveedor (nombre) | E2: Artículo (código) | F2: Artículo (nombre) | G2: Cantidad | H2: Precio POR UNIDAD | I2: PRECIO TOTAL
A3: 1 | B3: 46029 | C3: 5 | D3: =IF(Entradas[[#This Row],[Proveedor (código)]]="","",VLOOKUP(Entradas[[#This Row],[Proveedor (código)]],Proveedores[[#All],[Código]:[Nombre fiscal]],2,FALSE)) -> Almacen Banco de Alimentos | E3: 0671EM | F3: =IF(Entradas[[#This Row],[Artículo (código)]]="","",VLOOKUP(Entradas[[#This Row],[Artículo (código)]],Existencias!A:D,4,FALSE)) -> Chorizo Finas Hierbas x4 | G3: 1 | H3: =VLOOKUP(Entradas[[#This Row],[Artículo (código)]],Existencias!A:F,6,FALSE)*Entradas[[#This Row],[Cantidad]] -> 12.23 | I3: =Entradas[[#This Row],[Precio POR UNIDAD]]*Entradas[[#This Row],[Cantidad]] -> 12.23
A4: 1 | B4: 46029 | C4: 5 | D4: =IF(Entradas[[#This Row],[Proveedor (código)]]="","",VLOOKUP(Entradas[[#This Row],[Proveedor (código)]],Proveedores[[#All],[Código]:[Nombre fiscal]],2,FALSE)) -> Almacen Banco de Alimentos | E4: 0670EM | F4: =IF(Entradas[[#This Row],[Artículo (código)]]="","",VLOOKUP(Entradas[[#This Row],[Artículo (código)]],Existencias!A:D,4,FALSE)) -> Chorizo Parrillero x 4 | G4: 1 | H4: =VLOOKUP(Entradas[[#This Row],[Artículo (código)]],Existencias!A:F,6,FALSE)*Entradas[[#This Row],[Cantidad]] -> 8.54 | I4: =Entradas[[#This Row],[Precio POR UNIDAD]]*Entradas[[#This Row],[Cantidad]] -> 8.54
A5: 1 | B5: 46029 | C5: 5 | D5: =IF(Entradas[[#This Row],[Proveedor (código)]]="","",VLOOKUP(Entradas[[#This Row],[Proveedor (código)]],Proveedores[[#All],[Código]:[Nombre fiscal]],2,FALSE)) -> Almacen Banco de Alimentos | E5: 0669EM | F5: =IF(Entradas[[#This Row],[Artículo (código)]]="","",VLOOKUP(Entradas[[#This Row],[Artículo (código)]],Existencias!A:D,4,FALSE)) -> Chorizo Preco x 4 | G5: 6 | H5: =VLOOKUP(Entradas[[#This Row],[Artículo (código)]],Existencias!A:F,6,FALSE)*Entradas[[#This Row],[Cantidad]] -> 0 | I5: =Entradas[[#This Row],[Precio POR UNIDAD]]*Entradas[[#This Row],[Cantidad]] -> 0
A6: 1 | B6: 46029 | C6: 5 | D6: =IF(Entradas[[#This Row],[Proveedor (código)]]="","",VLOOKUP(Entradas[[#This Row],[Proveedor (código)]],Proveedores[[#All],[Código]:[Nombre fiscal]],2,FALSE)) -> Almacen Banco de Alimentos | E6: 0672EM | F6: =IF(Entradas[[#This Row],[Artículo (código)]]="","",VLOOKUP(Entradas[[#This Row],[Artículo (código)]],Existencias!A:D,4,FALSE)) -> Hot dog de pollo x 250 gr | G6: 18 | H6: =VLOOKUP(Entradas[[#This Row],[Artículo (código)]],Existencias!A:F,6,FALSE)*Entradas[[#This Row],[Cantidad]] -> 90.72 | I6: =Entradas[[#This Row],[Precio POR UNIDAD]]*Entradas[[#This Row],[Cantidad]] -> 1632.96
A7: 1 | B7: 46029 | C7: 8 | D7: =IF(Entradas[[#This Row],[Proveedor (código)]]="","",VLOOKUP(Entradas[[#This Row],[Proveedor (código)]],Proveedores[[#All],[Código]:[Nombre fiscal]],2,FALSE)) -> MOR | E7: 0474HU | F7: =IF(Entradas[[#This Row],[Artículo (código)]]="","",VLOOKUP(Entradas[[#This Row],[Artículo (código)]],Existencias!A:D,4,FALSE)) -> Huevo pardo | G7: 30 | H7: =VLOOKUP(Entradas[[#This Row],[Artículo (código)]],Existencias!A:F,6,FALSE)*Entradas[[#This Row],[Cantidad]] -> 0 | I7: =Entradas[[#This Row],[Precio POR UNIDAD]]*Entradas[[#This Row],[Cantidad]] -> 0
B8: 46031 | C8: 2 | D8: =IF(Entradas[[#This Row],[Proveedor (código)]]="","",VLOOKUP(Entradas[[#This Row],[Proveedor (código)]],Proveedores[[#All],[Código]:[Nombre fiscal]],2,FALSE)) -> PLAZA VEA B.A | E8: 0674EM | F8: =IF(Entradas[[#This Row],[Artículo (código)]]="","",VLOOKUP(Entradas[[#This Row],[Artículo (código)]],Existencias!A:D,4,FALSE)) -> Hot dog pavo | G8: 1 | H8: =VLOOKUP(Entradas[[#This Row],[Artículo (código)]],Existencias!A:F,6,FALSE)*Entradas[[#This Row],[Cantidad]] -> 1 | I8: =Entradas[[#This Row],[Precio POR UNIDAD]]*Entradas[[#This Row],[Cantidad]] -> 1
C9: 2 | D9: =IF(Entradas[[#This Row],[Proveedor (código)]]="","",VLOOKUP(Entradas[[#This Row],[Proveedor (código)]],Proveedores[[#All],[Código]:[Nombre fiscal]],2,FALSE)) -> PLAZA VEA B.A | E9: 0675EM | F9: =IF(Entradas[[#This Row],[Artículo (código)]]="","",VLOOKUP(Entradas[[#This Row],[Artículo (código)]],Existencias!A:D,4,FALSE)) -> Salchicha huachana | G9: 2 | H9: =VLOOKUP(Entradas[[#This Row],[Artículo (código)]],Existencias!A:F,6,FALSE)*Entradas[[#This Row],[Cantidad]] -> 4 | I9: =Entradas[[#This Row],[Precio POR UNIDAD]]*Entradas[[#This Row],[Cantidad]] -> 8
C10: 2 | D10: =IF(Entradas[[#This Row],[Proveedor (código)]]="","",VLOOKUP(Entradas[[#This Row],[Proveedor (código)]],Proveedores[[#All],[Código]:[Nombre fiscal]],2,FALSE)) -> PLAZA VEA B.A | E10: 0676EM | F10: =IF(Entradas[[#This Row],[Artículo (código)]]="","",VLOOKUP(Entradas[[#This Row],[Artículo (código)]],Existencias!A:D,4,FALSE)) -> Salchichon saborizado | G10: 1 | H10: =VLOOKUP(Entradas[[#This Row],[Artículo (código)]],Existencias!A:F,6,FALSE)*Entradas[[#This Row],[Cantidad]] -> 1 | I10: =Entradas[[#This Row],[Precio POR UNIDAD]]*Entradas[[#This Row],[Cantidad]] -> 1
B11: 46034 | C11: 4 | D11: =IF(Entradas[[#This Row],[Proveedor (código)]]="","",VLOOKUP(Entradas[[#This Row],[Proveedor (código)]],Proveedores[[#All],[Código]:[Nombre fiscal]],2,FALSE)) -> Metro B.A | E11: 0672EM | F11: =IF(Entradas[[#This Row],[Artículo (código)]]="","",VLOOKUP(Entradas[[#This Row],[Artículo (código)]],Existencias!A:D,4,FALSE)) -> Hot dog de pollo x 250 gr | G11: 8 | H11: =VLOOKUP(Entradas[[#This Row],[Artículo (código)]],Existencias!A:F,6,FALSE)*Entradas[[#This Row],[Cantidad]] -> 40.32 | I11: =Entradas[[#This Row],[Precio POR UNIDAD]]*Entradas[[#This Row],[Cantidad]] -> 322.56
B12: 46034 | C12: 4 | D12: =IF(Entradas[[#This Row],[Proveedor (código)]]="","",VLOOKUP(Entradas[[#This Row],[Proveedor (código)]],Proveedores[[#All],[Código]:[Nombre fiscal]],2,FALSE)) -> Metro B.A | E12: 0414LA | F12: =IF(Entradas[[#This Row],[Artículo (código)]]="","",VLOOKUP(Entradas[[#This Row],[Artículo (código)]],Existencias!A:D,4,FALSE)) -> Yogurt 120g bebible | G12: 19 | H12: =VLOOKUP(Entradas[[#This Row],[Artículo (código)]],Existencias!A:F,6,FALSE)*Entradas[[#This Row],[Cantidad]] -> 38.57 | I12: =Entradas[[#This Row],[Precio POR UNIDAD]]*Entradas[[#This Row],[Cantidad]] -> 732.83
B13: 46034 | C13: 4 | D13: =IF(Entradas[[#This Row],[Proveedor (código)]]="","",VLOOKUP(Entradas[[#This Row],[Proveedor (código)]],Proveedores[[#All],[Código]:[Nombre fiscal]],2,FALSE)) -> Metro B.A | E13: 0670EM | F13: =IF(Entradas[[#This Row],[Artículo (código)]]="","",VLOOKUP(Entradas[[#This Row],[Artículo (código)]],Existencias!A:D,4,FALSE)) -> Chorizo Parrillero x 4 | G13: 3 | H13: =VLOOKUP(Entradas[[#This Row],[Artículo (código)]],Existencias!A:F,6,FALSE)*Entradas[[#This Row],[Cantidad]] -> 25.62 | I13: =Entradas[[#This Row],[Precio POR UNIDAD]]*Entradas[[#This Row],[Cantidad]] -> 76.86
B14: 46034 | C14: 4 | D14: =IF(Entradas[[#This Row],[Proveedor (código)]]="","",VLOOKUP(Entradas[[#This Row],[Proveedor (código)]],Proveedores[[#All],[Código]:[Nombre fiscal]],2,FALSE)) -> Metro B.A | E14: 0160CR | F14: =IF(Entradas[[#This Row],[Artículo (código)]]="","",VLOOKUP(Entradas[[#This Row],[Artículo (código)]],Existencias!A:D,4,FALSE)) -> Arroz 5 kg | G14: 1 | H14: =VLOOKUP(Entradas[[#This Row],[Artículo (código)]],Existencias!A:F,6,FALSE)*Entradas[[#This Row],[Cantidad]] -> 24.95 | I14: =Entradas[[#This Row],[Precio POR UNIDAD]]*Entradas[[#This Row],[Cantidad]] -> 24.95
B15: 46034 | C15: 4 | D15: =IF(Entradas[[#This Row],[Proveedor (código)]]="","",VLOOKUP(Entradas[[#This Row],[Proveedor (código)]],Proveedores[[#All],[Código]:[Nombre fiscal]],2,FALSE)) -> Metro B.A | E15: 0187AZ | F15: =IF(Entradas[[#This Row],[Artículo (código)]]="","",VLOOKUP(Entradas[[#This Row],[Artículo (código)]],Existencias!A:D,4,FALSE)) -> Azucar blanca 2 kg | G15: 1 | H15: =VLOOKUP(Entradas[[#This Row],[Artículo (código)]],Existencias!A:F,6,FALSE)*Entradas[[#This Row],[Cantidad]] -> 7.36 | I15: =Entradas[[#This Row],[Precio POR UNIDAD]]*Entradas[[#This Row],[Cantidad]] -> 7.36
B16: 46034 | C16: 4 | D16: =IF(Entradas[[#This Row],[Proveedor (código)]]="","",VLOOKUP(Entradas[[#This Row],[Proveedor (código)]],Proveedores[[#All],[Código]:[Nombre fiscal]],2,FALSE)) -> Metro B.A | E16: 0185AZ | F16: =IF(Entradas[[#This Row],[Artículo (código)]]="","",VLOOKUP(Entradas[[#This Row],[Artículo (código)]],Existencias!A:D,4,FALSE)) -> Azucar blanca 1kg | G16: 1 | H16: =VLOOKUP(Entradas[[#This Row],[Artículo (código)]],Existencias!A:F,6,FALSE)*Entradas[[#This Row],[Cantidad]] -> 3.1 | I16: =Entradas[[#This Row],[Precio POR UNIDAD]]*Entradas[[#This Row],[Cantidad]] -> 3.1
B17: 46034 | C17: 4 | D17: =IF(Entradas[[#This Row],[Proveedor (código)]]="","",VLOOKUP(Entradas[[#This Row],[Proveedor (código)]],Proveedores[[#All],[Código]:[Nombre fiscal]],2,FALSE)) -> Metro B.A | E17: 0347FI | F17: =IF(Entradas[[#This Row],[Artículo (código)]]="","",VLOOKUP(Entradas[[#This Row],[Artículo (código)]],Existencias!A:D,4,FALSE)) -> Fideos cortos 250 gr | G17: 5 | H17: =VLOOKUP(Entradas[[#This Row],[Artículo (código)]],Existencias!A:F,6,FALSE)*Entradas[[#This Row],[Cantidad]] -> 12.9 | I17: =Entradas[[#This Row],[Precio POR UNIDAD]]*Entradas[[#This Row],[Cantidad]] -> 64.5
B18: 46034 | C18: 4 | D18: =IF(Entradas[[#This Row],[Proveedor (código)]]="","",VLOOKUP(Entradas[[#This Row],[Proveedor (código)]],Proveedores[[#All],[Código]:[Nombre fiscal]],2,FALSE)) -> Metro B.A | E18: 0344FI | F18: =IF(Entradas[[#This Row],[Artículo (código)]]="","",VLOOKUP(Entradas[[#This Row],[Artículo (código)]],Existencias!A:D,4,FALSE)) -> Fideos largos 500 gr | G18: 4 | H18: =VLOOKUP(Entradas[[#This Row],[Artículo (código)]],Existencias!A:F,6,FALSE)*Entradas[[#This Row],[Cantidad]] -> 10.84 | I18: =Entradas[[#This Row],[Precio POR UNIDAD]]*Entradas[[#This Row],[Cantidad]] -> 43.36
B19: 46034 | C19: 4 | D19: =IF(Entradas[[#This Row],[Proveedor (código)]]="","",VLOOKUP(Entradas[[#This Row],[Proveedor (código)]],Proveedores[[#All],[Código]:[Nombre fiscal]],2,FALSE)) -> Metro B.A | E19: 0266CN | F19: =IF(Entradas[[#This Row],[Artículo (código)]]="","",VLOOKUP(Entradas[[#This Row],[Artículo (código)]],Existencias!A:D,4,FALSE)) -> Sal Mesa 1kg | G19: 1 | H19: =VLOOKUP(Entradas[[#This Row],[Artículo (código)]],Existencias!A:F,6,FALSE)*Entradas[[#This Row],[Cantidad]] -> 1.67 | I19: =Entradas[[#This Row],[Precio POR UNIDAD]]*Entradas[[#This Row],[Cantidad]] -> 1.67
B20: 46034 | C20: 4 | D20: =IF(Entradas[[#This Row],[Proveedor (código)]]="","",VLOOKUP(Entradas[[#This Row],[Proveedor (código)]],Proveedores[[#All],[Código]:[Nombre fiscal]],2,FALSE)) -> Metro B.A | E20: 0345FI | F20: =IF(Entradas[[#This Row],[Artículo (código)]]="","",VLOOKUP(Entradas[[#This Row],[Artículo (código)]],Existencias!A:D,4,FALSE)) -> Fideos largos 900 gr | G20: 2 | H20: =VLOOKUP(Entradas[[#This Row],[Artículo (código)]],Existencias!A:F,6,FALSE)*Entradas[[#This Row],[Cantidad]] -> 9.5 | I20: =Entradas[[#This Row],[Precio POR UNIDAD]]*Entradas[[#This Row],[Cantidad]] -> 19
B21: 46034 | C21: 4 | D21: =IF(Entradas[[#This Row],[Proveedor (código)]]="","",VLOOKUP(Entradas[[#This Row],[Proveedor (código)]],Proveedores[[#All],[Código]:[Nombre fiscal]],2,FALSE)) -> Metro B.A | E21: 0149CR | F21: =IF(Entradas[[#This Row],[Artículo (código)]]="","",VLOOKUP(Entradas[[#This Row],[Artículo (código)]],Existencias!A:D,4,FALSE)) -> Avena 1 kl | G21: 1 | H21: =VLOOKUP(Entradas[[#This Row],[Artículo (código)]],Existencias!A:F,6,FALSE)*Entradas[[#This Row],[Cantidad]] -> 7.75 | I21: =Entradas[[#This Row],[Precio POR UNIDAD]]*Entradas[[#This Row],[Cantidad]] -> 7.75
B22: 46034 | C22: 4 | D22: =IF(Entradas[[#This Row],[Proveedor (código)]]="","",VLOOKUP(Entradas[[#This Row],[Proveedor (código)]],Proveedores[[#All],[Código]:[Nombre fiscal]],2,FALSE)) -> Metro B.A | E22: 0164CR | F22: =IF(Entradas[[#This Row],[Artículo (código)]]="","",VLOOKUP(Entradas[[#This Row],[Artículo (código)]],Existencias!A:D,4,FALSE)) -> Arroz Integral 1 kg | G22: 1 | H22: =VLOOKUP(Entradas[[#This Row],[Artículo (código)]],Existencias!A:F,6,FALSE)*Entradas[[#This Row],[Cantidad]] -> 4.69 | I22: =Entradas[[#This Row],[Precio POR UNIDAD]]*Entradas[[#This Row],[Cantidad]] -> 4.69
... B333: 46097 | C333: 4 | D333: =IF(Entradas[[#This Row],[Proveedor (código)]]="","",VLOOKUP(Entradas[[#This Row],[Proveedor (código)]],Proveedores[[#All],[Código]:[Nombre fiscal]],2,FALSE)) -> Metro B.A | E333: 0072ME | F333: =IF(Entradas[[#This Row],[Artículo (código)]]="","",VLOOKUP(Entradas[[#This Row],[Artículo (código)]],Existencias!A:D,4,FALSE)) -> Quinua Roja 500 gr | G333: 1 | H333: =VLOOKUP(Entradas[[#This Row],[Artículo (código)]],Existencias!A:F,6,FALSE)*Entradas[[#This Row],[Cantidad]] -> 0 | I333: =Entradas[[#This Row],[Precio POR UNIDAD]]*Entradas[[#This Row],[Cantidad]] -> 0
B334: 46097 | C334: 4 | D334: =IF(Entradas[[#This Row],[Proveedor (código)]]="","",VLOOKUP(Entradas[[#This Row],[Proveedor (código)]],Proveedores[[#All],[Código]:[Nombre fiscal]],2,FALSE)) -> Metro B.A | E334: 0118CO | F334: =IF(Entradas[[#This Row],[Artículo (código)]]="","",VLOOKUP(Entradas[[#This Row],[Artículo (código)]],Existencias!A:D,4,FALSE)) -> Trozo de atun aceite lata | G334: 4 | H334: =VLOOKUP(Entradas[[#This Row],[Artículo (código)]],Existencias!A:F,6,FALSE) -> 0 | I334: =Entradas[[#This Row],[Precio POR UNIDAD]]*Entradas[[#This Row],[Cantidad]] -> 0
B335: 46097 | C335: 2 | D335: =IF(Entradas[[#This Row],[Proveedor (código)]]="","",VLOOKUP(Entradas[[#This Row],[Proveedor (código)]],Proveedores[[#All],[Código]:[Nombre fiscal]],2,FALSE)) -> PLAZA VEA B.A | E335: 0522CE | F335: =IF(Entradas[[#This Row],[Artículo (código)]]="","",VLOOKUP(Entradas[[#This Row],[Artículo (código)]],Existencias!A:D,4,FALSE)) -> bondiola | G335: 0.9 | H335: =VLOOKUP(Entradas[[#This Row],[Artículo (código)]],Existencias!A:F,6,FALSE) -> 0 | I335: =Entradas[[#This Row],[Precio POR UNIDAD]]*Entradas[[#This Row],[Cantidad]] -> 0
B336: 46097 | C336: 2 | D336: =IF(Entradas[[#This Row],[Proveedor (código)]]="","",VLOOKUP(Entradas[[#This Row],[Proveedor (código)]],Proveedores[[#All],[Código]:[Nombre fiscal]],2,FALSE)) -> PLAZA VEA B.A | E336: 0502AV | F336: =IF(Entradas[[#This Row],[Artículo (código)]]="","",VLOOKUP(Entradas[[#This Row],[Artículo (código)]],Existencias!A:D,4,FALSE)) -> Alas natural | G336: 0.95 | H336: =VLOOKUP(Entradas[[#This Row],[Artículo (código)]],Existencias!A:F,6,FALSE) -> 0 | I336: =Entradas[[#This Row],[Precio POR UNIDAD]]*Entradas[[#This Row],[Cantidad]] -> 0
B337: 46097 | C337: 2 | D337: =IF(Entradas[[#This Row],[Proveedor (código)]]="","",VLOOKUP(Entradas[[#This Row],[Proveedor (código)]],Proveedores[[#All],[Código]:[Nombre fiscal]],2,FALSE)) -> PLAZA VEA B.A | E337: 0500AV | F337: =IF(Entradas[[#This Row],[Artículo (código)]]="","",VLOOKUP(Entradas[[#This Row],[Artículo (código)]],Existencias!A:D,4,FALSE)) -> Higado de pollo | G337: 1.56 | H337: =VLOOKUP(Entradas[[#This Row],[Artículo (código)]],Existencias!A:F,6,FALSE) -> 0 | I337: =Entradas[[#This Row],[Precio POR UNIDAD]]*Entradas[[#This Row],[Cantidad]] -> 0
B338: 46097 | C338: 2 | D338: =IF(Entradas[[#This Row],[Proveedor (código)]]="","",VLOOKUP(Entradas[[#This Row],[Proveedor (código)]],Proveedores[[#All],[Código]:[Nombre fiscal]],2,FALSE)) -> PLAZA VEA B.A | E338: 0497AV | F338: =IF(Entradas[[#This Row],[Artículo (código)]]="","",VLOOKUP(Entradas[[#This Row],[Artículo (código)]],Existencias!A:D,4,FALSE)) -> Pollo piernas c/ encuentro bandeja | G338: 2.23 | H338: =VLOOKUP(Entradas[[#This Row],[Artículo (código)]],Existencias!A:F,6,FALSE) -> 0 | I338: =Entradas[[#This Row],[Precio POR UNIDAD]]*Entradas[[#This Row],[Cantidad]] -> 0
B339: 46097 | C339: 2 | D339: =IF(Entradas[[#This Row],[Proveedor (código)]]="","",VLOOKUP(Entradas[[#This Row],[Proveedor (código)]],Proveedores[[#All],[Código]:[Nombre fiscal]],2,FALSE)) -> PLAZA VEA B.A | E339: 0516AV | F339: =IF(Entradas[[#This Row],[Artículo (código)]]="","",VLOOKUP(Entradas[[#This Row],[Artículo (código)]],Existencias!A:D,4,FALSE)) -> Piernas de pollo kg | G339: 2.06 | H339: =VLOOKUP(Entradas[[#This Row],[Artículo (código)]],Existencias!A:F,6,FALSE) -> 12.12 | I339: =Entradas[[#This Row],[Precio POR UNIDAD]]*Entradas[[#This Row],[Cantidad]] -> 24.9672
B340: 46097 | C340: 2 | D340: =IF(Entradas[[#This Row],[Proveedor (código)]]="","",VLOOKUP(Entradas[[#This Row],[Proveedor (código)]],Proveedores[[#All],[Código]:[Nombre fiscal]],2,FALSE)) -> PLAZA VEA B.A | E340: 0528CE | F340: =IF(Entradas[[#This Row],[Artículo (código)]]="","",VLOOKUP(Entradas[[#This Row],[Artículo (código)]],Existencias!A:D,4,FALSE)) -> Medallon de lomo | G340: 1 | H340: =VLOOKUP(Entradas[[#This Row],[Artículo (código)]],Existencias!A:F,6,FALSE) -> 0 | I340: =Entradas[[#This Row],[Precio POR UNIDAD]]*Entradas[[#This Row],[Cantidad]] -> 0
B341: 46097 | C341: 2 | D341: =IF(Entradas[[#This Row],[Proveedor (código)]]="","",VLOOKUP(Entradas[[#This Row],[Proveedor (código)]],Proveedores[[#All],[Código]:[Nombre fiscal]],2,FALSE)) -> PLAZA VEA B.A | E341: 0159CR | F341: =IF(Entradas[[#This Row],[Artículo (código)]]="","",VLOOKUP(Entradas[[#This Row],[Artículo (código)]],Existencias!A:D,4,FALSE)) -> Arroz 1 kg | G341: 3 | H341: =VLOOKUP(Entradas[[#This Row],[Artículo (código)]],Existencias!A:F,6,FALSE) -> 4.73 | I341: =Entradas[[#This Row],[Precio POR UNIDAD]]*Entradas[[#This Row],[Cantidad]] -> 14.19
B342: 46097 | C342: 2 | D342: =IF(Entradas[[#This Row],[Proveedor (código)]]="","",VLOOKUP(Entradas[[#This Row],[Proveedor (código)]],Proveedores[[#All],[Código]:[Nombre fiscal]],2,FALSE)) -> PLAZA VEA B.A | E342: 0126CO | F342: =IF(Entradas[[#This Row],[Artículo (código)]]="","",VLOOKUP(Entradas[[#This Row],[Artículo (código)]],Existencias!A:D,4,FALSE)) -> Piña en almibar 500 gr lata | G342: 10 | H342: =VLOOKUP(Entradas[[#This Row],[Artículo (código)]],Existencias!A:F,6,FALSE) -> 0 | I342: =Entradas[[#This Row],[Precio POR UNIDAD]]*Entradas[[#This Row],[Cantidad]] -> 0
B343: 46097 | C343: 2 | D343: =IF(Entradas[[#This Row],[Proveedor (código)]]="","",VLOOKUP(Entradas[[#This Row],[Proveedor (código)]],Proveedores[[#All],[Código]:[Nombre fiscal]],2,FALSE)) -> PLAZA VEA B.A | E343: 0229IN | F343: =IF(Entradas[[#This Row],[Artículo (código)]]="","",VLOOKUP(Entradas[[#This Row],[Artículo (código)]],Existencias!A:D,4,FALSE)) -> Chocolisto marshmallow 150 | G343: 68 | H343: =VLOOKUP(Entradas[[#This Row],[Artículo (código)]],Existencias!A:F,6,FALSE) -> 0 | I343: =Entradas[[#This Row],[Precio POR UNIDAD]]*Entradas[[#This Row],[Cantidad]] -> 0
B344: 46097 | C344: 2 | D344: =IF(Entradas[[#This Row],[Proveedor (código)]]="","",VLOOKUP(Entradas[[#This Row],[Proveedor (código)]],Proveedores[[#All],[Código]:[Nombre fiscal]],2,FALSE)) -> PLAZA VEA B.A | E344: 0051ME | F344: =IF(Entradas[[#This Row],[Artículo (código)]]="","",VLOOKUP(Entradas[[#This Row],[Artículo (código)]],Existencias!A:D,4,FALSE)) -> Pallar 500 gr | G344: 3 | H344: =VLOOKUP(Entradas[[#This Row],[Artículo (código)]],Existencias!A:F,6,FALSE) -> 0 | I344: =Entradas[[#This Row],[Precio POR UNIDAD]]*Entradas[[#This Row],[Cantidad]] -> 0
B345: 46097 | C345: 2 | D345: =IF(Entradas[[#This Row],[Proveedor (código)]]="","",VLOOKUP(Entradas[[#This Row],[Proveedor (código)]],Proveedores[[#All],[Código]:[Nombre fiscal]],2,FALSE)) -> PLAZA VEA B.A | E345: 0065ME | F345: =IF(Entradas[[#This Row],[Artículo (código)]]="","",VLOOKUP(Entradas[[#This Row],[Artículo (código)]],Existencias!A:D,4,FALSE)) -> Quinua 500 gr | G345: 1 | H345: =VLOOKUP(Entradas[[#This Row],[Artículo (código)]],Existencias!A:F,6,FALSE) -> 8.21 | I345: =Entradas[[#This Row],[Precio POR UNIDAD]]*Entradas[[#This Row],[Cantidad]] -> 8.21
... B350: 46097 | C350: 2 | D350: =IF(Entradas[[#This Row],[Proveedor (código)]]="","",VLOOKUP(Entradas[[#This Row],[Proveedor (código)]],Proveedores[[#All],[Código]:[Nombre fiscal]],2,FALSE)) -> PLAZA VEA B.A | E350: 0395LA | F350: =IF(Entradas[[#This Row],[Artículo (código)]]="","",VLOOKUP(Entradas[[#This Row],[Artículo (código)]],Existencias!A:D,4,FALSE)) -> Leche Evaporada 390 gr lata | G350: 6 | H350: =VLOOKUP(Entradas[[#This Row],[Artículo (código)]],Existencias!A:F,6,FALSE) -> 0 | I350: =Entradas[[#This Row],[Precio POR UNIDAD]]*Entradas[[#This Row],[Cantidad]] -> 0
B351: 46097 | C351: 2 | D351: =IF(Entradas[[#This Row],[Proveedor (código)]]="","",VLOOKUP(Entradas[[#This Row],[Proveedor (código)]],Proveedores[[#All],[Código]:[Nombre fiscal]],2,FALSE)) -> PLAZA VEA B.A | F351: =IF(Entradas[[#This Row],[Artículo (código)]]="","",VLOOKUP(Entradas[[#This Row],[Artículo (código)]],Existencias!A:D,4,FALSE)) | H351: =VLOOKUP(Entradas[[#This Row],[Artículo (código)]],Existencias!A:F,6,FALSE) -> #N/A | I351: =Entradas[[#This Row],[Precio POR UNIDAD]]*Entradas[[#This Row],[Cantidad]] -> #N/A
B352: 46097 | C352: 2 | D352: =IF(Entradas[[#This Row],[Proveedor (código)]]="","",VLOOKUP(Entradas[[#This Row],[Proveedor (código)]],Proveedores[[#All],[Código]:[Nombre fiscal]],2,FALSE)) -> PLAZA VEA B.A | F352: =IF(Entradas[[#This Row],[Artículo (código)]]="","",VLOOKUP(Entradas[[#This Row],[Artículo (código)]],Existencias!A:D,4,FALSE)) | H352: =VLOOKUP(Entradas[[#This Row],[Artículo (código)]],Existencias!A:F,6,FALSE) -> #N/A | I352: =Entradas[[#This Row],[Precio POR UNIDAD]]*Entradas[[#This Row],[Cantidad]] -> #N/A
D353: =IF(Entradas[[#This Row],[Proveedor (código)]]="","",VLOOKUP(Entradas[[#This Row],[Proveedor (código)]],Proveedores[[#All],[Código]:[Nombre fiscal]],2,FALSE)) | F353: =IF(Entradas[[#This Row],[Artículo (código)]]="","",VLOOKUP(Entradas[[#This Row],[Artículo (código)]],Existencias!A:D,4,FALSE)) | H353: =VLOOKUP(Entradas[[#This Row],[Artículo (código)]],Existencias!A:F,6,FALSE) -> #N/A | I353: =Entradas[[#This Row],[Precio POR UNIDAD]]*Entradas[[#This Row],[Cantidad]] -> #N/A
D354: =IF(Entradas[[#This Row],[Proveedor (código)]]="","",VLOOKUP(Entradas[[#This Row],[Proveedor (código)]],Proveedores[[#All],[Código]:[Nombre fiscal]],2,FALSE)) | F354: =IF(Entradas[[#This Row],[Artículo (código)]]="","",VLOOKUP(Entradas[[#This Row],[Artículo (código)]],Existencias!A:D,4,FALSE)) | H354: =VLOOKUP(Entradas[[#This Row],[Artículo (código)]],Existencias!A:F,6,FALSE) -> #N/A | I354: =Entradas[[#This Row],[Precio POR UNIDAD]]*Entradas[[#This Row],[Cantidad]] -> #N/A
D355: =IF(Entradas[[#This Row],[Proveedor (código)]]="","",VLOOKUP(Entradas[[#This Row],[Proveedor (código)]],Proveedores[[#All],[Código]:[Nombre fiscal]],2,FALSE)) | F355: =IF(Entradas[[#This Row],[Artículo (código)]]="","",VLOOKUP(Entradas[[#This Row],[Artículo (código)]],Existencias!A:D,4,FALSE)) | H355: =VLOOKUP(Entradas[[#This Row],[Artículo (código)]],Existencias!A:F,6,FALSE) -> #N/A | I355: =Entradas[[#This Row],[Precio POR UNIDAD]]*Entradas[[#This Row],[Cantidad]] -> #N/A
...

Sheet Salidas
B2: Fecha | C2: Cliente (código) | D2: Cliente (nombre) | E2: Artículo (código) | F2: Artículo (nombre) | G2: Cantidad | H2: Precio
A3: 1 | B3: 45661 | C3: 1 | D3: Aldimi | E3: 0149CR | F3: =IF(Salidas[[#This Row],[Artículo (código)]]="","",VLOOKUP(Salidas[[#This Row],[Artículo (código)]],Existencias!A:D,4,FALSE)) -> Avena 1 kl | G3: 1 | H3: =IF(Salidas[[#This Row],[Artículo (código)]]="","",VLOOKUP(Salidas[[#This Row],[Artículo (código)]],Existencias!A:F,7,FALSE)) -> #REF!
B4: 45661 | C4: 1 | D4: Aldimi | E4: 0395LA | F4: =IF(Salidas[[#This Row],[Artículo (código)]]="","",VLOOKUP(Salidas[[#This Row],[Artículo (código)]],Existencias!A:D,4,FALSE)) -> Leche Evaporada 390 gr lata | G4: 7 | H4: =IF(Salidas[[#This Row],[Artículo (código)]]="","",VLOOKUP(Salidas[[#This Row],[Artículo (código)]],Existencias!A:F,7,FALSE)) -> #REF!
B5: 46026 | C5: 1 | D5: Aldimi | E5: 0474HU | F5: =IF(Salidas[[#This Row],[Artículo (código)]]="","",VLOOKUP(Salidas[[#This Row],[Artículo (código)]],Existencias!A:D,4,FALSE)) -> Huevo pardo | G5: 25 | H5: =IF(Salidas[[#This Row],[Artículo (código)]]="","",VLOOKUP(Salidas[[#This Row],[Artículo (código)]],Existencias!A:F,7,FALSE)) -> #REF!
B6: 46026 | C6: 1 | D6: Aldimi | E6: 0190AZ | F6: =IF(Salidas[[#This Row],[Artículo (código)]]="","",VLOOKUP(Salidas[[#This Row],[Artículo (código)]],Existencias!A:D,4,FALSE)) -> Azucar rubia 1kg | G6: 1 | H6: =IF(Salidas[[#This Row],[Artículo (código)]]="","",VLOOKUP(Salidas[[#This Row],[Artículo (código)]],Existencias!A:F,7,FALSE)) -> #REF!
B7: 46026 | C7: 1 | D7: Aldimi | E7: 0345FI | F7: =IF(Salidas[[#This Row],[Artículo (código)]]="","",VLOOKUP(Salidas[[#This Row],[Artículo (código)]],Existencias!A:D,4,FALSE)) -> Fideos largos 900 gr | G7: 4 | H7: =IF(Salidas[[#This Row],[Artículo (código)]]="","",VLOOKUP(Salidas[[#This Row],[Artículo (código)]],Existencias!A:F,7,FALSE)) -> #REF!
B8: 46026 | C8: 1 | D8: Aldimi | E8: 0118CO | F8: =IF(Salidas[[#This Row],[Artículo (código)]]="","",VLOOKUP(Salidas[[#This Row],[Artículo (código)]],Existencias!A:D,4,FALSE)) -> Trozo de atun aceite lata | G8: 20 | H8: =IF(Salidas[[#This Row],[Artículo (código)]]="","",VLOOKUP(Salidas[[#This Row],[Artículo (código)]],Existencias!A:F,7,FALSE)) -> #REF!
B9: 46026 | C9: 1 | D9: Aldimi | E9: 0493AV | F9: =IF(Salidas[[#This Row],[Artículo (código)]]="","",VLOOKUP(Salidas[[#This Row],[Artículo (código)]],Existencias!A:D,4,FALSE)) -> Pollo fresco entero | G9: 2 | H9: =IF(Salidas[[#This Row],[Artículo (código)]]="","",VLOOKUP(Salidas[[#This Row],[Artículo (código)]],Existencias!A:F,7,FALSE)) -> #REF!
B10: 46026 | C10: 1 | D10: Aldimi | E10: 0293CN | F10: =IF(Salidas[[#This Row],[Artículo (código)]]="","",VLOOKUP(Salidas[[#This Row],[Artículo (código)]],Existencias!A:D,4,FALSE)) -> Salsa de tomate 145 gr | G10: 1 | H10: =IF(Salidas[[#This Row],[Artículo (código)]]="","",VLOOKUP(Salidas[[#This Row],[Artículo (código)]],Existencias!A:F,7,FALSE)) -> #REF!
B11: 46026 | C11: 1 | D11: Aldimi | E11: 0266CN | F11: =IF(Salidas[[#This Row],[Artículo (código)]]="","",VLOOKUP(Salidas[[#This Row],[Artículo (código)]],Existencias!A:D,4,FALSE)) -> Sal Mesa 1kg | G11: 1 | H11: =IF(Salidas[[#This Row],[Artículo (código)]]="","",VLOOKUP(Salidas[[#This Row],[Artículo (código)]],Existencias!A:F,7,FALSE)) -> #REF!
B12: 46027 | C12: 1 | D12: Aldimi | E12: 0149CR | F12: =IF(Salidas[[#This Row],[Artículo (código)]]="","",VLOOKUP(Salidas[[#This Row],[Artículo (código)]],Existencias!A:D,4,FALSE)) -> Avena 1 kl | G12: 1 | H12: =IF(Salidas[[#This Row],[Artículo (código)]]="","",VLOOKUP(Salidas[[#This Row],[Artículo (código)]],Existencias!A:F,7,FALSE)) -> #REF!
B13: 46027 | C13: 1 | D13: Aldimi | E13: 0474HU | F13: =IF(Salidas[[#This Row],[Artículo (código)]]="","",VLOOKUP(Salidas[[#This Row],[Artículo (código)]],Existencias!A:D,4,FALSE)) -> Huevo pardo | G13: 30 | H13: =IF(Salidas[[#This Row],[Artículo (código)]]="","",VLOOKUP(Salidas[[#This Row],[Artículo (código)]],Existencias!A:F,7,FALSE)) -> #REF!
B14: 46027 | C14: 1 | D14: Aldimi | E14: 0190AZ | F14: =IF(Salidas[[#This Row],[Artículo (código)]]="","",VLOOKUP(Salidas[[#This Row],[Artículo (código)]],Existencias!A:D,4,FALSE)) -> Azucar rubia 1kg | G14: 1 | H14: =IF(Salidas[[#This Row],[Artículo (código)]]="","",VLOOKUP(Salidas[[#This Row],[Artículo (código)]],Existencias!A:F,7,FALSE)) -> #REF!
B15: 46027 | C15: 1 | D15: Aldimi | E15: 0059ME | F15: =IF(Salidas[[#This Row],[Artículo (código)]]="","",VLOOKUP(Salidas[[#This Row],[Artículo (código)]],Existencias!A:D,4,FALSE)) -> Papa Seca 1 kg | G15: 3 | H15: =IF(Salidas[[#This Row],[Artículo (código)]]="","",VLOOKUP(Salidas[[#This Row],[Artículo (código)]],Existencias!A:F,7,FALSE)) -> #REF!
... B267: 46063 | C267: 1 | D267: Aldimi | E267: 0149CR | F267: =IF(Salidas[[#This Row],[Artículo (código)]]="","",VLOOKUP(Salidas[[#This Row],[Artículo (código)]],Existencias!A:D,4,FALSE)) -> Avena 1 kl | G267: 1 | H267: =IF(Salidas[[#This Row],[Artículo (código)]]="","",VLOOKUP(Salidas[[#This Row],[Artículo (código)]],Existencias!A:F,7,FALSE)) -> #REF!
B268: 46063 | C268: 1 | D268: Aldimi | E268: 0047ME | F268: =IF(Salidas[[#This Row],[Artículo (código)]]="","",VLOOKUP(Salidas[[#This Row],[Artículo (código)]],Existencias!A:D,4,FALSE)) -> Moron 1 kl | G268: 0.75. | H268: =IF(Salidas[[#This Row],[Artículo (código)]]="","",VLOOKUP(Salidas[[#This Row],[Artículo (código)]],Existencias!A:F,7,FALSE)) -> #REF!
B269: 46063 | C269: 1 | D269: Aldimi | E269: 0493AV | F269: =IF(Salidas[[#This Row],[Artículo (código)]]="","",VLOOKUP(Salidas[[#This Row],[Artículo (código)]],Existencias!A:D,4,FALSE)) -> Pollo fresco entero | G269: 2 | H269: =IF(Salidas[[#This Row],[Artículo (código)]]="","",VLOOKUP(Salidas[[#This Row],[Artículo (código)]],Existencias!A:F,7,FALSE)) -> #REF!
B270: 46063 | C270: 1 | D270: Aldimi | E270: 0160CR | F270: =IF(Salidas[[#This Row],[Artículo (código)]]="","",VLOOKUP(Salidas[[#This Row],[Artículo (código)]],Existencias!A:D,4,FALSE)) -> Arroz 5 kg | G270: 1 | H270: =IF(Salidas[[#This Row],[Artículo (código)]]="","",VLOOKUP(Salidas[[#This Row],[Artículo (código)]],Existencias!A:F,7,FALSE)) -> #REF!
B271: 46063 | C271: 1 | D271: Aldimi | E271: 0090AC | F271: =IF(Salidas[[#This Row],[Artículo (código)]]="","",VLOOKUP(Salidas[[#This Row],[Artículo (código)]],Existencias!A:D,4,FALSE)) -> Aceite Vegetal 900 ml | G271: 1 | H271: =IF(Salidas[[#This Row],[Artículo (código)]]="","",VLOOKUP(Salidas[[#This Row],[Artículo (código)]],Existencias!A:F,7,FALSE)) -> #REF!
B272: 46063 | C272: 1 | D272: Aldimi | E272: 0265CN | F272: =IF(Salidas[[#This Row],[Artículo (código)]]="","",VLOOKUP(Salidas[[#This Row],[Artículo (código)]],Existencias!A:D,4,FALSE)) -> Sal cocina 1kg | G272: 2 | H272: =IF(Salidas[[#This Row],[Artículo (código)]]="","",VLOOKUP(Salidas[[#This Row],[Artículo (código)]],Existencias!A:F,7,FALSE)) -> #REF!
B273: 46064 | C273: 1 | D273: Aldimi | E273: 0149CR | F273: =IF(Salidas[[#This Row],[Artículo (código)]]="","",VLOOKUP(Salidas[[#This Row],[Artículo (código)]],Existencias!A:D,4,FALSE)) -> Avena 1 kl | G273: 1 | H273: =IF(Salidas[[#This Row],[Artículo (código)]]="","",VLOOKUP(Salidas[[#This Row],[Artículo (código)]],Existencias!A:F,7,FALSE)) -> #REF!
B274: 46064 | C274: 1 | D274: Aldimi | E274: 0474HU | F274: =IF(Salidas[[#This Row],[Artículo (código)]]="","",VLOOKUP(Salidas[[#This Row],[Artículo (código)]],Existencias!A:D,4,FALSE)) -> Huevo pardo | G274: 20 | H274: =IF(Salidas[[#This Row],[Artículo (código)]]="","",VLOOKUP(Salidas[[#This Row],[Artículo (código)]],Existencias!A:F,7,FALSE)) -> #REF!
B275: 46064 | C275: 1 | D275: Aldimi | E275: 0160CR | F275: =IF(Salidas[[#This Row],[Artículo (código)]]="","",VLOOKUP(Salidas[[#This Row],[Artículo (código)]],Existencias!A:D,4,FALSE)) -> Arroz 5 kg | G275: 1 | H275: =IF(Salidas[[#This Row],[Artículo (código)]]="","",VLOOKUP(Salidas[[#This Row],[Artículo (código)]],Existencias!A:F,7,FALSE)) -> #REF!
B276: 46064 | C276: 1 | D276: Aldimi | E276: 0511AV | F276: =IF(Salidas[[#This Row],[Artículo (código)]]="","",VLOOKUP(Salidas[[#This Row],[Artículo (código)]],Existencias!A:D,4,FALSE)) -> Medallones de pavo | G276: 3 | H276: =IF(Salidas[[#This Row],[Artículo (código)]]="","",VLOOKUP(Salidas[[#This Row],[Artículo (código)]],Existencias!A:F,7,FALSE)) -> #REF!
B277: 46064 | C277: 1 | D277: Aldimi | E277: 0090AC | F277: =IF(Salidas[[#This Row],[Artículo (código)]]="","",VLOOKUP(Salidas[[#This Row],[Artículo (código)]],Existencias!A:D,4,FALSE)) -> Aceite Vegetal 900 ml | G277: 2 | H277: =IF(Salidas[[#This Row],[Artículo (código)]]="","",VLOOKUP(Salidas[[#This Row],[Artículo (código)]],Existencias!A:F,7,FALSE)) -> #REF!
B278: 46064 | C278: 1 | D278: Aldimi | E278: 0347FI | F278: =IF(Salidas[[#This Row],[Artículo (código)]]="","",VLOOKUP(Salidas[[#This Row],[Artículo (código)]],Existencias!A:D,4,FALSE)) -> Fideos cortos 250 gr | G278: 3 | H278: =IF(Salidas[[#This Row],[Artículo (código)]]="","",VLOOKUP(Salidas[[#This Row],[Artículo (código)]],Existencias!A:F,7,FALSE)) -> #REF!
B279: 46064 | C279: 1 | D279: Aldimi | E279: 0332GE | F279: =IF(Salidas[[#This Row],[Artículo (código)]]="","",VLOOKUP(Salidas[[#This Row],[Artículo (código)]],Existencias!A:D,4,FALSE)) -> GELATINA 160 gr | G279: 4 | H279: =IF(Salidas[[#This Row],[Artículo (código)]]="","",VLOOKUP(Salidas[[#This Row],[Artículo (código)]],Existencias!A:F,7,FALSE)) -> #REF!
B280: 46065 | C280: 1 | D280: Aldimi | E280: 0066ME | F280: =IF(Salidas[[#This Row],[Artículo (código)]]="","",VLOOKUP(Salidas[[#This Row],[Artículo (código)]],Existencias!A:D,4,FALSE)) -> Quinua 1 kg | G280: 0.75 | H280: =IF(Salidas[[#This Row],[Artículo (código)]]="","",VLOOKUP(Salidas[[#This Row],[Artículo (código)]],Existencias!A:F,7,FALSE)) -> #REF!
... B343: 46075 | C343: 1 | D343: Aldimi | E343: 0090AC | F343: =IF(Salidas[[#This Row],[Artículo (código)]]="","",VLOOKUP(Salidas[[#This Row],[Artículo (código)]],Existencias!A:D,4,FALSE)) -> Aceite Vegetal 900 ml | G343: 1 | H343: =IF(Salidas[[#This Row],[Artículo (código)]]="","",VLOOKUP(Salidas[[#This Row],[Artículo (código)]],Existencias!A:F,7,FALSE)) -> #REF!
B344: 46075 | C344: 1 | D344: =IF(Entradas[[#This Row],[Proveedor (código)]]="","",VLOOKUP(Entradas[[#This Row],[Proveedor (código)]],Proveedores[[#All],[Código]:[Nombre fiscal]],2,FALSE)) -> PLAZA VEA B.A | E344: 0116CO | F344: =IF(Salidas[[#This Row],[Artículo (código)]]="","",VLOOKUP(Salidas[[#This Row],[Artículo (código)]],Existencias!A:D,4,FALSE)) -> Filete de atun aceite lata | G344: 12 | H344: =IF(Salidas[[#This Row],[Artículo (código)]]="","",VLOOKUP(Salidas[[#This Row],[Artículo (código)]],Existencias!A:F,7,FALSE)) -> #REF!
B345: 46076 | C345: 1 | D345: =IF(Entradas[[#This Row],[Proveedor (código)]]="","",VLOOKUP(Entradas[[#This Row],[Proveedor (código)]],Proveedores[[#All],[Código]:[Nombre fiscal]],2,FALSE)) -> PLAZA VEA B.A | E345: 0149CR | F345: =IF(Salidas[[#This Row],[Artículo (código)]]="","",VLOOKUP(Salidas[[#This Row],[Artículo (código)]],Existencias!A:D,4,FALSE)) -> Avena 1 kl | G345: 1 | H345: =IF(Salidas[[#This Row],[Artículo (código)]]="","",VLOOKUP(Salidas[[#This Row],[Artículo (código)]],Existencias!A:F,7,FALSE)) -> #REF!
B346: 46076 | C346: 1 | D346: =IF(Entradas[[#This Row],[Proveedor (código)]]="","",VLOOKUP(Entradas[[#This Row],[Proveedor (código)]],Proveedores[[#All],[Código]:[Nombre fiscal]],2,FALSE)) -> PLAZA VEA B.A | E346: 0474HU | F346: =IF(Salidas[[#This Row],[Artículo (código)]]="","",VLOOKUP(Salidas[[#This Row],[Artículo (código)]],Existencias!A:D,4,FALSE)) -> Huevo pardo | G346: 6 | H346: =IF(Salidas[[#This Row],[Artículo (código)]]="","",VLOOKUP(Salidas[[#This Row],[Artículo (código)]],Existencias!A:F,7,FALSE)) -> #REF!
B347: 46076 | C347: 1 | D347: =IF(Entradas[[#This Row],[Proveedor (código)]]="","",VLOOKUP(Entradas[[#This Row],[Proveedor (código)]],Proveedores[[#All],[Código]:[Nombre fiscal]],2,FALSE)) -> PLAZA VEA B.A | E347: 0160CR | F347: =IF(Salidas[[#This Row],[Artículo (código)]]="","",VLOOKUP(Salidas[[#This Row],[Artículo (código)]],Existencias!A:D,4,FALSE)) -> Arroz 5 kg | G347: 1 | H347: =IF(Salidas[[#This Row],[Artículo (código)]]="","",VLOOKUP(Salidas[[#This Row],[Artículo (código)]],Existencias!A:F,7,FALSE)) -> #REF!
B348: 46076 | C348: 1 | D348: =IF(Entradas[[#This Row],[Proveedor (código)]]="","",VLOOKUP(Entradas[[#This Row],[Proveedor (código)]],Proveedores[[#All],[Código]:[Nombre fiscal]],2,FALSE)) -> PLAZA VEA B.A | E348: 0066ME | F348: =IF(Salidas[[#This Row],[Artículo (código)]]="","",VLOOKUP(Salidas[[#This Row],[Artículo (código)]],Existencias!A:D,4,FALSE)) -> Quinua 1 kg | G348: 3 | H348: =IF(Salidas[[#This Row],[Artículo (código)]]="","",VLOOKUP(Salidas[[#This Row],[Artículo (código)]],Existencias!A:F,7,FALSE)) -> #REF!
B349: 46076 | C349: 1 | D349: =IF(Entradas[[#This Row],[Proveedor (código)]]="","",VLOOKUP(Entradas[[#This Row],[Proveedor (código)]],Proveedores[[#All],[Código]:[Nombre fiscal]],2,FALSE)) -> PLAZA VEA B.A | E349: 0294CN | F349: =IF(Salidas[[#This Row],[Artículo (código)]]="","",VLOOKUP(Salidas[[#This Row],[Artículo (código)]],Existencias!A:D,4,FALSE)) -> Salsa de tomate 290 gr | G349: 1 | H349: =IF(Salidas[[#This Row],[Artículo (código)]]="","",VLOOKUP(Salidas[[#This Row],[Artículo (código)]],Existencias!A:F,7,FALSE)) -> #REF!
B350: 46076 | C350: 1 | D350: =IF(Entradas[[#This Row],[Proveedor (código)]]="","",VLOOKUP(Entradas[[#This Row],[Proveedor (código)]],Proveedores[[#All],[Código]:[Nombre fiscal]],2,FALSE)) -> PLAZA VEA B.A | E350: 0493AV | F350: =IF(Salidas[[#This Row],[Artículo (código)]]="","",VLOOKUP(Salidas[[#This Row],[Artículo (código)]],Existencias!A:D,4,FALSE)) -> Pollo fresco entero | G350: 7 | H350: =IF(Salidas[[#This Row],[Artículo (código)]]="","",VLOOKUP(Salidas[[#This Row],[Artículo (código)]],Existencias!A:F,7,FALSE)) -> #REF!
